Workbook
Name ListaDisciplinas: tbDisciplinas[DISCIPLINA]
Name ListaFornecedores: tbFornecedores[FORNECEDOR]
Name ListaObras: tbObras[CÓDIGO]
Name ListaStatusMedição: tbStatusMedição[]
Name ListaStatusOrçamento: tbStatusOrçamento[Status orçamento]
Name ListaSubdisciplinas: tbSubdisciplinas[SUBDISCIPLINA]
Name SegmentaçãodeDados_CÓDIGO: #N/A
Name SegmentaçãodeDados_OBRA1: #N/A

Sheet Resumo
F2: ORÇADO | G2: CONTRATADO | H2: A CONTRATAR | I2: MEDIDO | J2: SALDO A MEDIR
F3: =GETPIVOTDATA("[Measures].[Soma de ORÇAMENTO BASE]",Cálculos!$B$1) -> 871259.2 | G3: =GETPIVOTDATA("[Measures].[Soma de VALOR CONTRATADO]",Cálculos!$B$1) -> 748921.2 | H3: =GETPIVOTDATA("[Measures].[Soma de SALDO A CONTRATAR]",Cálculos!$B$1) -> 122338 | I3: =GETPIVOTDATA("[Measures].[Soma de VALOR MEDIDO]",Cálculos!$B$1) -> 170452.99 | J3: =GETPIVOTDATA("[Measures].[Soma de SALDO MEDIÇÃO]",Cálculos!$B$1) -> 578468.21

Sheet Listas
A1: OBRA_ID | B1: CC | C1: CÓDIGO | D1: NOME | E1: ENDEREÇO | G1: DISCIPLINA_ID | H1: DISCIPLINA | I1: COD_DISCIPLINA | K1: DISCIPLINA_ID | L1: DISCIPLINA | M1: COD_DISCIPLINA | N1: SUBDISCIPLINA | O1: COD_SUBDISCIPLINA | Q1: FORNECEDOR_ID | R1: ID SIENGE | S1: FORNECEDOR | T1: TIPO | X1: Status orçamento | Z1: Status medições
A2: OBR001 | B2: 29 | C2: PAI3 | D2: Paineiras 3 | G2: DIS001 | H2: ARQUITETURA | I2: ARQ | K2: SUB001 | L2: ARQUITETURA | M2: ARQ | N2: ARQUITERURA LEGAL | O2: ARQ_LEGAL | Q2: FOR001 | R2: 2306 | S2: SOMA | T2: ARQUITETURA | X2: A contratar | Z2: A medir
A3: OBR002 | B3: 33 | C3: OTI | D3: Otília | G3: DIS002 | H3: ESTRUTURA | I3: EST | K3: SUB002 | L3: ARQUITETURA | M3: ARQ | N3: ARQUITETURA EXECUTIVA | O3: ARQ_EXE | Q3: FOR002 | R3: 27 | S3: MBUIATE | T3: ESTRUTURA | X3: Em cotação | Z3: Medido
A4: OBR003 | B4: 47 | C4: ALT | D4: Altamira | G4: DIS003 | H4: COMPLEMENTARES | I4: COMP | K4: SUB003 | L4: ESTRUTURA | M4: EST | N4: ESTRUTURA DE CONCRETO | O4: EST_CON | Q4: FOR003 | R4: 1532 | S4: ARCIS | T4: COMPLEMENTARES | X4: Em cotratação | Z4: Pago
A5: OBR004 | B5: 53 | C5: MON | D5: Monterré | G5: DIS004 | H5: PLANIALTIMÉTRICO | I5: PLAN | K5: SUB004 | L5: ESTRUTURA | M5: EST | N5: ESTRUTURA DE AÇO | O5: EST_MET | Q5: FOR004 | R5: 2665 | S5: VERTICAL | T5: ORÇAMENTO | X5: Contratado | Z5: Cancelada
A6: OBR005 | B6: 65 | C6: GAL | D6: Galassi | G6: DIS005 | H6: SONDAGEM | I6: SON | K6: SUB005 | L6: ESTRUTURA | M6: EST | N6: ESTRUTURA DE MADEIRA | O6: EST_MAD | Q6: FOR005 | R6: 2859 | S6: DALTON | T6: INTERIORES | X6: Cancelado
A7: OBR006 | B7: 71 | C7: PQSUL | D7: Parque Sul | G7: DIS006 | H7: FUNDAÇÃO | I7: FUN | K7: SUB006 | L7: ESTRUTURA | M7: EST | N7: ESCORAMENTO | O7: EST_ESC | Q7: FOR006 | R7: 2712 | S7: KARINA | T7: INTERIORES
A8: OBR007 | B8: 77 | C8: LIB | D8: Liberdade | G8: DIS007 | H8: INTERIORES | I8: INT | K8: SUB007 | L8: ESTRUTURA | M8: EST | N8: FUNDAÇÃO SUPERFICIAL | O8: EST_FUN | Q8: FOR007 | R8: 125 | S8: GEOMETA | T8: SONDAGEM
A9: OBR008 | B9: 82 | C9: UNA | D9: UNA | G9: DIS008 | H9: FACHADA | I9: FCH | K9: SUB008 | L9: ESTRUTURA | M9: EST | N9: CONTENÇÕES | O9: EST_CON | Q9: FOR008 | R9: 1763 | S9: GEOMETRIA | T9: FUNDAÇÃO
A10: OBR009 | B10: 84 | C10: STM | D10: Santa Mônica | G10: DIS009 | H10: ESQUADRIAS | I10: ESQ | K10: SUB025 | L10: ESTRUTURA | M10: EST | N10: PISO SUBSOLO | O10: EST_PISO | Q10: FOR009 | R10: 2691 | S10: EMMIG | T10: ESTRUTURA
A11: OBR010 | B11: 85 | C11: SEFAZ | D11: Galassi SEFAZ | G11: DIS010 | H11: IMPERMEABILIZAÇÃO | I11: IMP | K11: SUB009 | L11: COMPLEMENTARES | M11: COMP | N11: COMPLEMENTARES | O11: COMP | Q11: FOR010 | R11: 2739 | S11: BINV | T11: COMPLEMENTARES
G12: DIS011 | H12: SEGURANÇA | I12: SEG | K12: SUB010 | L12: COMPLEMENTARES | M12: COMP | N12: HIDROSSANITÁRIO | O12: HID | Q12: FOR011 | R12: 2637 | S12: DOMANI | T12: DESEMPENHO
G13: DIS012 | H13: DESEMPENHO | I13: DES | K13: SUB011 | L13: COMPLEMENTARES | M13: COMP | N13: ELÉTRICO | O13: ELE | Q13: FOR012 | R13: 447 | S13: VANIA | T13: SONDAGEM
G14: DIS013 | H14: INFRAESTRUTURA | I14: INF | K14: SUB012 | L14: COMPLEMENTARES | M14: COMP | N14: COMUNICAÇÃO | O14: COM | Q14: FOR013 | R14: 475 | S14: JP SERVIÇOS | T14: SONDAGEM
G15: DIS014 | H15: LEGALIZAÇÃO | I15: LEG | K15: SUB013 | L15: COMPLEMENTARES | M15: COMP | N15: SPDA | O15: SPDA | Q15: FOR014 | R15: 1062 | S15: GÊMEAS | T15: ARQUITETURA
G16: DIS015 | H16: ORÇAMENTO | I16: ORC | K16: SUB014 | L16: COMPLEMENTARES | M16: COMP | N16: GÁS | O16: GLP | Q16: FOR015 | R16: 663 | S16: IDEAL | T16: PLANIALTIMÉTRICO
G17: DIS016 | H17: PLANEJAMENTO | I17: PLA | K17: SUB015 | L17: COMPLEMENTARES | M17: COMP | N17: CLIMATIZAÇÃO | O17: CLI | Q17: FOR016 | R17: 2740 | S17: GEOMAP | T17: PLANIALTIMÉTRICO
K18: SUB016 | L18: COMPLEMENTARES | M18: COMP | N18: INCÊNDIO | O18: PCI | Q18: FOR017 | R18: 2778 | S18: THAIS | T18: LEGALIZAÇÃO
K19: SUB017 | L19: COMPLEMENTARES | M19: COMP | N19: PRESSURIZAÇÃO | O19: PRE | Q19: FOR018 | R19: 844 | S19: COSTA | T19: LEGALIZAÇÃO
K20: SUB018 | L20: COMPLEMENTARES | M20: COMP | N20: MARKUP | O20: MKP | Q20: FOR019 | R20: 60 | S20: CARTÓRIO | T20: LEGALIZAÇÃO
K21: SUB019 | L21: COMPLEMENTARES | M21: COMP | N21: PISCINA | O21: PIS | Q21: FOR020 | R21: 370 | S21: CREA | T21: LEGALIZAÇÃO
K22: SUB020 | L22: COMPLEMENTARES | M22: COMP | N22: COMPATIBILIZAÇÃO | O22: MOD | Q22: FOR021 | R22: 1942 | S22: CRT | T22: LEGALIZAÇÃO
K23: SUB021 | L23: PLANIALTIMÉTRICO | M23: PLAN | N23: PLANIALTIMÉTRICO | O23: PLAN | Q23: FOR022 | R23: 1653 | S23: PMU | T23: LEGALIZAÇÃO
K24: SUB022 | L24: SONDAGEM | M24: SON | N24: SONDAGEM | O24: SON | Q24: FOR023 | R24: 2 | S24: RECEITA | T24: LEGALIZAÇÃO
K25: SUB023 | L25: FUNDAÇÃO | M25: FUN | N25: FUNDAÇÃO PROFUNDA | O25: FUN_PRO | Q25: FOR024 | S25: TAXAS | T25: LEGALIZAÇÃO
K26: SUB026 | L26: INTERIORES | M26: INT | N26: INTERIORES | O26: INT
K27: SUB027 | L27: INTERIORES | M27: INT | N27: PAISAGISMO | O27: PSG
K28: SUB028 | L28: FACHADA | M28: FCH | N28: FACHADA | O28: FCH
K29: SUB029 | L29: ESQUADRIAS | M29: ESQ | N29: ESQUADRIAS | O29: ESQ
K30: SUB030 | L30: IMPERMEABILIZAÇÃO | M30: IMP | N30: IMPERMEABILIZAÇÃO | O30: IMP
K31: SUB031 | L31: SEGURANÇA | M31: SEG | N31: SEGURANÇA | O31: CFTV
K32: SUB032 | L32: DESEMPENHO | M32: DES | N32: DESEMPENHO | O32: DES
K33: SUB033 | L33: DESEMPENHO | M33: DES | N33: LAUDO DE RUÍDO | O33: RUI
K34: SUB034 | L34: INFRAESTRUTURA | M34: INF | N34: INTERLIGAÇÃO ÁGUA | O34: INF_DMAE
K35: SUB035 | L35: INFRAESTRUTURA | M35: INF | N35: INTERLIGAÇÃO ELÉTRICA | O35: INF_CEMIG
K36: SUB036 | L36: INFRAESTRUTURA | M36: INF | N36: INTERLIGAÇÃO ESGOTO | O36: INF_DMAE
K37: SUB037 | L37: INFRAESTRUTURA | M37: INF | N37: INTERLIGAÇÃO DRENAGEM PLUVIAL | O37: INF_DMAE
... K60: SUB060 | L60: PLANEJAMENTO | M60: PLA | N60: EXECUTIVO | O60: EXE

Sheet Cálculos
B1: Soma de ORÇAMENTO BASE | C1: Soma de VALOR CONTRATADO | D1: Soma de SALDO A CONTRATAR | E1: Soma de VALOR MEDIDO | F1: Soma de SALDO MEDIÇÃO
B2: 871259.2 | C2: 748921.2 | D2: 122338 | E2: 170452.99 | F2: 578468.21
B7: Rótulos de Linha | C7: DESEMBOLSO | D7: ACUMULADO
B8: 26/01 | C8: 45000 | D8: 45000
B9: 26/02 | C9: 2850 | D9: 47850
B10: 26/03 | C10: 9993 | D10: 57843
B11: 26/04 | C11: 9993 | D11: 67836
B12: 26/05 | C12: 3399.66 | D12: 71235.66
B13: 26/06 | C13: 65138.71 | D13: 136374.37
B14: 26/07 | C14: 79078.62 | D14: 215452.99
B15: 26/08 | C15: 34661 | D15: 250113.99
B16: 26/09 | C16: 55953 | D16: 306066.99
B17: 26/10 | C17: 58037.23 | D17: 364104.22
B18: 26/11 | C18: 39179 | D18: 403283.22
B19: 26/12 | C19: 41915 | D19: 445198.22
B20: 27/01 | C20: 6490 | D20: 451688.22
B21: Total Geral | C21: 451688.22

Sheet tbOrçamento
A1: OBRA | B1: NOME OBRA | C1: DISCIPLINA | D1: SUBDISCIPLINA | E1: ORÇAMENTO BASE | F1: VALOR CONTRATADO | G1: SALDO A CONTRATAR | H1: VALOR MEDIDO | I1: SALDO MEDIÇÃO | J1: STATUS
A2: ALT | B2: =_xlfn.XLOOKUP(tbOrçamento[[#This Row],[OBRA]],tbObras[CÓDIGO],tbObras[NOME],"Não encontrado",0) -> Altamira | C2: SONDAGEM | D2: SONDAGEM | E2: 56000 | F2: =SUMIFS(tbContratos[VALOR CONTRATO],tbContratos[OBRA],tbOrçamento[[#This Row],[OBRA]],tbContratos[SUBDISCIPLINA],tbOrçamento[[#This Row],[SUBDISCIPLINA]]) -> 21880.65 | G2: =tbOrçamento[[#This Row],[ORÇAMENTO BASE ]]-tbOrçamento[[#This Row],[VALOR CONTRATADO]] -> 34119.35 | H2: =SUMIFS(tbContratos[VALOR MEDIDO],tbContratos[OBRA],tbOrçamento[[#This Row],[OBRA]],tbContratos[SUBDISCIPLINA],tbOrçamento[[#This Row],[SUBDISCIPLINA]]) -> 21880.65 | I2: =tbOrçamento[[#This Row],[VALOR CONTRATADO]]-tbOrçamento[[#This Row],[VALOR MEDIDO]] -> 0 | J2: Contratado
A3: ALT | B3: =_xlfn.XLOOKUP(tbOrçamento[[#This Row],[OBRA]],tbObras[CÓDIGO],tbObras[NOME],"Não encontrado",0) -> Altamira | C3: PLANIALTIMÉTRICO | D3: PLANIALTIMÉTRICO | E3: 5000 | F3: =SUMIFS(tbContratos[VALOR CONTRATO],tbContratos[OBRA],tbOrçamento[[#This Row],[OBRA]],tbContratos[SUBDISCIPLINA],tbOrçamento[[#This Row],[SUBDISCIPLINA]]) -> 4550 | G3: =tbOrçamento[[#This Row],[ORÇAMENTO BASE ]]-tbOrçamento[[#This Row],[VALOR CONTRATADO]] -> 450 | H3: =SUMIFS(tbContratos[VALOR MEDIDO],tbContratos[OBRA],tbOrçamento[[#This Row],[OBRA]],tbContratos[SUBDISCIPLINA],tbOrçamento[[#This Row],[SUBDISCIPLINA]]) -> 4550 | I3: =tbOrçamento[[#This Row],[VALOR CONTRATADO]]-tbOrçamento[[#This Row],[VALOR MEDIDO]] -> 0 | J3: Contratado
A4: ALT | B4: =_xlfn.XLOOKUP(tbOrçamento[[#This Row],[OBRA]],tbObras[CÓDIGO],tbObras[NOME],"Não encontrado",0) -> Altamira | C4: ARQUITETURA | D4: ARQUITERURA LEGAL | E4: 108000 | F4: =SUMIFS(tbContratos[VALOR CONTRATO],tbContratos[OBRA],tbOrçamento[[#This Row],[OBRA]],tbContratos[SUBDISCIPLINA],tbOrçamento[[#This Row],[SUBDISCIPLINA]]) -> 108000 | G4: =tbOrçamento[[#This Row],[ORÇAMENTO BASE ]]-tbOrçamento[[#This Row],[VALOR CONTRATADO]] -> 0 | H4: =SUMIFS(tbContratos[VALOR MEDIDO],tbContratos[OBRA],tbOrçamento[[#This Row],[OBRA]],tbContratos[SUBDISCIPLINA],tbOrçamento[[#This Row],[SUBDISCIPLINA]]) -> 102600 | I4: =tbOrçamento[[#This Row],[VALOR CONTRATADO]]-tbOrçamento[[#This Row],[VALOR MEDIDO]] -> 5400 | J4: Contratado
A5: ALT | B5: =_xlfn.XLOOKUP(tbOrçamento[[#This Row],[OBRA]],tbObras[CÓDIGO],tbObras[NOME],"Não encontrado",0) -> Altamira | C5: ARQUITETURA | D5: ARQUITETURA EXECUTIVA | E5: 108000 | F5: =SUMIFS(tbContratos[VALOR CONTRATO],tbContratos[OBRA],tbOrçamento[[#This Row],[OBRA]],tbContratos[SUBDISCIPLINA],tbOrçamento[[#This Row],[SUBDISCIPLINA]]) -> 0 | G5: =tbOrçamento[[#This Row],[ORÇAMENTO BASE ]]-tbOrçamento[[#This Row],[VALOR CONTRATADO]] -> 108000 | H5: =SUMIFS(tbContratos[VALOR MEDIDO],tbContratos[OBRA],tbOrçamento[[#This Row],[OBRA]],tbContratos[SUBDISCIPLINA],tbOrçamento[[#This Row],[SUBDISCIPLINA]]) -> 0 | I5: =tbOrçamento[[#This Row],[VALOR CONTRATADO]]-tbOrçamento[[#This Row],[VALOR MEDIDO]] -> 0 | J5: A contratar
A6: ALT | B6: =_xlfn.XLOOKUP(tbOrçamento[[#This Row],[OBRA]],tbObras[CÓDIGO],tbObras[NOME],"Não encontrado",0) -> Altamira | C6: ESTRUTURA | D6: ESTRUTURA DE CONCRETO | E6: 90000 | F6: =SUMIFS(tbContratos[VALOR CONTRATO],tbContratos[OBRA],tbOrçamento[[#This Row],[OBRA]],tbContratos[SUBDISCIPLINA],tbOrçamento[[#This Row],[SUBDISCIPLINA]]) -> 90000 | G6: =tbOrçamento[[#This Row],[ORÇAMENTO BASE ]]-tbOrçamento[[#This Row],[VALOR CONTRATADO]] -> 0 | H6: =SUMIFS(tbContratos[VALOR MEDIDO],tbContratos[OBRA],tbOrçamento[[#This Row],[OBRA]],tbContratos[SUBDISCIPLINA],tbOrçamento[[#This Row],[SUBDISCIPLINA]]) -> 18000 | I6: =tbOrçamento[[#This Row],[VALOR CONTRATADO]]-tbOrçamento[[#This Row],[VALOR MEDIDO]] -> 72000 | J6: Contratado
A7: ALT | B7: =_xlfn.XLOOKUP(tbOrçamento[[#This Row],[OBRA]],tbObras[CÓDIGO],tbObras[NOME],"Não encontrado",0) -> Altamira | C7: FUNDAÇÃO | D7: FUNDAÇÃO PROFUNDA | E7: 25000 | F7: =SUMIFS(tbContratos[VALOR CONTRATO],tbContratos[OBRA],tbOrçamento[[#This Row],[OBRA]],tbContratos[SUBDISCIPLINA],tbOrçamento[[#This Row],[SUBDISCIPLINA]]) -> 25000 | G7: =tbOrçamento[[#This Row],[ORÇAMENTO BASE ]]-tbOrçamento[[#This Row],[VALOR CONTRATADO]] -> 0 | H7: =SUMIFS(tbContratos[VALOR MEDIDO],tbContratos[OBRA],tbOrçamento[[#This Row],[OBRA]],tbContratos[SUBDISCIPLINA],tbOrçamento[[#This Row],[SUBDISCIPLINA]]) -> 0 | I7: =tbOrçamento[[#This Row],[VALOR CONTRATADO]]-tbOrçamento[[#This Row],[VALOR MEDIDO]] -> 25000 | J7: Contratado
A8: ALT | B8: =_xlfn.XLOOKUP(tbOrçamento[[#This Row],[OBRA]],tbObras[CÓDIGO],tbObras[NOME],"Não encontrado",0) -> Altamira | C8: FUNDAÇÃO | D8: PISO SUBSOLO | E8: 5000 | F8: =SUMIFS(tbContratos[VALOR CONTRATO],tbContratos[OBRA],tbOrçamento[[#This Row],[OBRA]],tbContratos[SUBDISCIPLINA],tbOrçamento[[#This Row],[SUBDISCIPLINA]]) -> 0 | G8: =tbOrçamento[[#This Row],[ORÇAMENTO BASE ]]-tbOrçamento[[#This Row],[VALOR CONTRATADO]] -> 5000 | H8: =SUMIFS(tbContratos[VALOR MEDIDO],tbContratos[OBRA],tbOrçamento[[#This Row],[OBRA]],tbContratos[SUBDISCIPLINA],tbOrçamento[[#This Row],[SUBDISCIPLINA]]) -> 0 | I8: =tbOrçamento[[#This Row],[VALOR CONTRATADO]]-tbOrçamento[[#This Row],[VALOR MEDIDO]] -> 0 | J8: A contratar
A9: ALT | B9: =_xlfn.XLOOKUP(tbOrçamento[[#This Row],[OBRA]],tbObras[CÓDIGO],tbObras[NOME],"Não encontrado",0) -> Altamira | C9: COMPLEMENTARES | D9: COMPLEMENTARES | E9: 150000 | F9: =SUMIFS(tbContratos[VALOR CONTRATO],tbContratos[OBRA],tbOrçamento[[#This Row],[OBRA]],tbContratos[SUBDISCIPLINA],tbOrçamento[[#This Row],[SUBDISCIPLINA]]) -> 290000 | G9: =tbOrçamento[[#This Row],[ORÇAMENTO BASE ]]-tbOrçamento[[#This Row],[VALOR CONTRATADO]] -> -140000 | H9: =SUMIFS(tbContratos[VALOR MEDIDO],tbContratos[OBRA],tbOrçamento[[#This Row],[OBRA]],tbContratos[SUBDISCIPLINA],tbOrçamento[[#This Row],[SUBDISCIPLINA]]) -> 109000 | I9: =tbOrçamento[[#This Row],[VALOR CONTRATADO]]-tbOrçamento[[#This Row],[VALOR MEDIDO]] -> 181000 | J9: Contratado
A10: ALT | B10: =_xlfn.XLOOKUP(tbOrçamento[[#This Row],[OBRA]],tbObras[CÓDIGO],tbObras[NOME],"Não encontrado",0) -> Altamira | C10: INTERIORES | D10: INTERIORES | E10: 34500 | F10: =SUMIFS(tbContratos[VALOR CONTRATO],tbContratos[OBRA],tbOrçamento[[#This Row],[OBRA]],tbContratos[SUBDISCIPLINA],tbOrçamento[[#This Row],[SUBDISCIPLINA]]) -> 39500 | G10: =tbOrçamento[[#This Row],[ORÇAMENTO BASE ]]-tbOrçamento[[#This Row],[VALOR CONTRATADO]] -> -5000 | H10: =SUMIFS(tbContratos[VALOR MEDIDO],tbContratos[OBRA],tbOrçamento[[#This Row],[OBRA]],tbContratos[SUBDISCIPLINA],tbOrçamento[[#This Row],[SUBDISCIPLINA]]) -> 20700 | I10: =tbOrçamento[[#This Row],[VALOR CONTRATADO]]-tbOrçamento[[#This Row],[VALOR MEDIDO]] -> 18800 | J10: Contratado
A11: ALT | B11: =_xlfn.XLOOKUP(tbOrçamento[[#This Row],[OBRA]],tbObras[CÓDIGO],tbObras[NOME],"Não encontrado",0) -> Altamira | C11: FACHADA | D11: FACHADA | E11: 15000 | F11: =SUMIFS(tbContratos[VALOR CONTRATO],tbContratos[OBRA],tbOrçamento[[#This Row],[OBRA]],tbContratos[SUBDISCIPLINA],tbOrçamento[[#This Row],[SUBDISCIPLINA]]) -> 0 | G11: =tbOrçamento[[#This Row],[ORÇAMENTO BASE ]]-tbOrçamento[[#This Row],[VALOR CONTRATADO]] -> 15000 | H11: =SUMIFS(tbContratos[VALOR MEDIDO],tbContratos[OBRA],tbOrçamento[[#This Row],[OBRA]],tbContratos[SUBDISCIPLINA],tbOrçamento[[#This Row],[SUBDISCIPLINA]]) -> 0 | I11: =tbOrçamento[[#This Row],[VALOR CONTRATADO]]-tbOrçamento[[#This Row],[VALOR MEDIDO]] -> 0 | J11: A contratar
A12: ALT | B12: =_xlfn.XLOOKUP(tbOrçamento[[#This Row],[OBRA]],tbObras[CÓDIGO],tbObras[NOME],"Não encontrado",0) -> Altamira | C12: ESQUADRIAS | D12: ESQUADRIAS | E12: 20000 | F12: =SUMIFS(tbContratos[VALOR CONTRATO],tbContratos[OBRA],tbOrçamento[[#This Row],[OBRA]],tbContratos[SUBDISCIPLINA],tbOrçamento[[#This Row],[SUBDISCIPLINA]]) -> 0 | G12: =tbOrçamento[[#This Row],[ORÇAMENTO BASE ]]-tbOrçamento[[#This Row],[VALOR CONTRATADO]] -> 20000 | H12: =SUMIFS(tbContratos[VALOR MEDIDO],tbContratos[OBRA],tbOrçamento[[#This Row],[OBRA]],tbContratos[SUBDISCIPLINA],tbOrçamento[[#This Row],[SUBDISCIPLINA]]) -> 0 | I12: =tbOrçamento[[#This Row],[VALOR CONTRATADO]]-tbOrçamento[[#This Row],[VALOR MEDIDO]] -> 0 | J12: A contratar
A13: ALT | B13: =_xlfn.XLOOKUP(tbOrçamento[[#This Row],[OBRA]],tbObras[CÓDIGO],tbObras[NOME],"Não encontrado",0) -> Altamira | C13: IMPERMEABILIZAÇÃO | D13: IMPERMEABILIZAÇÃO | E13: 15000 | F13: =SUMIFS(tbContratos[VALOR CONTRATO],tbContratos[OBRA],tbOrçamento[[#This Row],[OBRA]],tbContratos[SUBDISCIPLINA],tbOrçamento[[#This Row],[SUBDISCIPLINA]]) -> 0 | G13: =tbOrçamento[[#This Row],[ORÇAMENTO BASE ]]-tbOrçamento[[#This Row],[VALOR CONTRATADO]] -> 15000 | H13: =SUMIFS(tbContratos[VALOR MEDIDO],tbContratos[OBRA],tbOrçamento[[#This Row],[OBRA]],tbContratos[SUBDISCIPLINA],tbOrçamento[[#This Row],[SUBDISCIPLINA]]) -> 0 | I13: =tbOrçamento[[#This Row],[VALOR CONTRATADO]]-tbOrçamento[[#This Row],[VALOR MEDIDO]] -> 0 | J13: A contratar
... A40: GAL | B40: =_xlfn.XLOOKUP(tbOrçamento[[#This Row],[OBRA]],tbObras[CÓDIGO],tbObras[NOME],"Não encontrado",0) -> Galassi | C40: INFRAESTRUTURA | D40: INTERLIGAÇÃO ELÉTRICA | E40: 10000 | F40: =SUMIFS(tbContratos[VALOR CONTRATO],tbContratos[OBRA],tbOrçamento[[#This Row],[OBRA]],tbContratos[SUBDISCIPLINA],tbOrçamento[[#This Row],[SUBDISCIPLINA]]) -> 0 | G40: =tbOrçamento[[#This Row],[ORÇAMENTO BASE ]]-tbOrçamento[[#This Row],[VALOR CONTRATADO]] -> 10000 | H40: =SUMIFS(tbContratos[VALOR MEDIDO],tbContratos[OBRA],tbOrçamento[[#This Row],[OBRA]],tbContratos[SUBDISCIPLINA],tbOrçamento[[#This Row],[SUBDISCIPLINA]]) -> 0 | I40: =tbOrçamento[[#This Row],[VALOR CONTRATADO]]-tbOrçamento[[#This Row],[VALOR MEDIDO]] -> 0 | J40: A contratar
A41: GAL | B41: =_xlfn.XLOOKUP(tbOrçamento[[#This Row],[OBRA]],tbObras[CÓDIGO],tbObras[NOME],"Não encontrado",0) -> Galassi | C41: INFRAESTRUTURA | D41: PROLONGAMENTO REDE | F41: =SUMIFS(tbContratos[VALOR CONTRATO],tbContratos[OBRA],tbOrçamento[[#This Row],[OBRA]],tbContratos[SUBDISCIPLINA],tbOrçamento[[#This Row],[SUBDISCIPLINA]]) -> 0 | G41: =tbOrçamento[[#This Row],[ORÇAMENTO BASE ]]-tbOrçamento[[#This Row],[VALOR CONTRATADO]] -> 0 | H41: =SUMIFS(tbContratos[VALOR MEDIDO],tbContratos[OBRA],tbOrçamento[[#This Row],[OBRA]],tbContratos[SUBDISCIPLINA],tbOrçamento[[#This Row],[SUBDISCIPLINA]]) -> 0 | I41: =tbOrçamento[[#This Row],[VALOR CONTRATADO]]-tbOrçamento[[#This Row],[VALOR MEDIDO]] -> 0 | J41: A contratar
A42: GAL | B42: =_xlfn.XLOOKUP(tbOrçamento[[#This Row],[OBRA]],tbObras[CÓDIGO],tbObras[NOME],"Não encontrado",0) -> Galassi | C42: ORÇAMENTO | D42: PARAMÉTRICO | E42: 10000 | F42: =SUMIFS(tbContratos[VALOR CONTRATO],tbContratos[OBRA],tbOrçamento[[#This Row],[OBRA]],tbContratos[SUBDISCIPLINA],tbOrçamento[[#This Row],[SUBDISCIPLINA]]) -> 6248.31 | G42: =tbOrçamento[[#This Row],[ORÇAMENTO BASE ]]-tbOrçamento[[#This Row],[VALOR CONTRATADO]] -> 3751.69 | H42: =SUMIFS(tbContratos[VALOR MEDIDO],tbContratos[OBRA],tbOrçamento[[#This Row],[OBRA]],tbContratos[SUBDISCIPLINA],tbOrçamento[[#This Row],[SUBDISCIPLINA]]) -> 1874.493 | I42: =tbOrçamento[[#This Row],[VALOR CONTRATADO]]-tbOrçamento[[#This Row],[VALOR MEDIDO]] -> 4373.817 | J42: Contratado
A43: GAL | B43: =_xlfn.XLOOKUP(tbOrçamento[[#This Row],[OBRA]],tbObras[CÓDIGO],tbObras[NOME],"Não encontrado",0) -> Galassi | C43: ORÇAMENTO | D43: EXECUTIVO | E43: 25000 | F43: =SUMIFS(tbContratos[VALOR CONTRATO],tbContratos[OBRA],tbOrçamento[[#This Row],[OBRA]],tbContratos[SUBDISCIPLINA],tbOrçamento[[#This Row],[SUBDISCIPLINA]]) -> 0 | G43: =tbOrçamento[[#This Row],[ORÇAMENTO BASE ]]-tbOrçamento[[#This Row],[VALOR CONTRATADO]] -> 25000 | H43: =SUMIFS(tbContratos[VALOR MEDIDO],tbContratos[OBRA],tbOrçamento[[#This Row],[OBRA]],tbContratos[SUBDISCIPLINA],tbOrçamento[[#This Row],[SUBDISCIPLINA]]) -> 0 | I43: =tbOrçamento[[#This Row],[VALOR CONTRATADO]]-tbOrçamento[[#This Row],[VALOR MEDIDO]] -> 0 | J43: A contratar
A44: GAL | B44: =_xlfn.XLOOKUP(tbOrçamento[[#This Row],[OBRA]],tbObras[CÓDIGO],tbObras[NOME],"Não encontrado",0) -> Galassi | C44: PLANEJAMENTO | D44: EXECUTIVO | E44: 15000 | F44: =SUMIFS(tbContratos[VALOR CONTRATO],tbContratos[OBRA],tbOrçamento[[#This Row],[OBRA]],tbContratos[SUBDISCIPLINA],tbOrçamento[[#This Row],[SUBDISCIPLINA]]) -> 0 | G44: =tbOrçamento[[#This Row],[ORÇAMENTO BASE ]]-tbOrçamento[[#This Row],[VALOR CONTRATADO]] -> 15000 | H44: =SUMIFS(tbContratos[VALOR MEDIDO],tbContratos[OBRA],tbOrçamento[[#This Row],[OBRA]],tbContratos[SUBDISCIPLINA],tbOrçamento[[#This Row],[SUBDISCIPLINA]]) -> 0 | I44: =tbOrçamento[[#This Row],[VALOR CONTRATADO]]-tbOrçamento[[#This Row],[VALOR MEDIDO]] -> 0 | J44: A contratar
A45: GAL | B45: =_xlfn.XLOOKUP(tbOrçamento[[#This Row],[OBRA]],tbObras[CÓDIGO],tbObras[NOME],"Não encontrado",0) -> Galassi | C45: LEGALIZAÇÃO | D45: LEGALIZAÇÃO | E45: 304579.2 | F45: =SUMIFS(tbContratos[VALOR CONTRATO],tbContratos[OBRA],tbOrçamento[[#This Row],[OBRA]],tbContratos[SUBDISCIPLINA],tbOrçamento[[#This Row],[SUBDISCIPLINA]]) -> 304579.2 | G45: =tbOrçamento[[#This Row],[ORÇAMENTO BASE ]]-tbOrçamento[[#This Row],[VALOR CONTRATADO]] -> 0 | H45: =SUMIFS(tbContratos[VALOR MEDIDO],tbContratos[OBRA],tbOrçamento[[#This Row],[OBRA]],tbContratos[SUBDISCIPLINA],tbOrçamento[[#This Row],[SUBDISCIPLINA]]) -> 18111.22 | I45: =tbOrçamento[[#This Row],[VALOR CONTRATADO]]-tbOrçamento[[#This Row],[VALOR MEDIDO]] -> 286467.98 | J45: A contratar
A46: PQSUL | B46: =_xlfn.XLOOKUP(tbOrçamento[[#This Row],[OBRA]],tbObras[CÓDIGO],tbObras[NOME],"Não encontrado",0) -> Parque Sul | C46: SONDAGEM | D46: SONDAGEM | E46: 25000 | F46: =SUMIFS(tbContratos[VALOR CONTRATO],tbContratos[OBRA],tbOrçamento[[#This Row],[OBRA]],tbContratos[SUBDISCIPLINA],tbOrçamento[[#This Row],[SUBDISCIPLINA]]) -> 23556.1 | G46: =tbOrçamento[[#This Row],[ORÇAMENTO BASE ]]-tbOrçamento[[#This Row],[VALOR CONTRATADO]] -> 1443.9 | H46: =SUMIFS(tbContratos[VALOR MEDIDO],tbContratos[OBRA],tbOrçamento[[#This Row],[OBRA]],tbContratos[SUBDISCIPLINA],tbOrçamento[[#This Row],[SUBDISCIPLINA]]) -> 23556.1 | I46: =tbOrçamento[[#This Row],[VALOR CONTRATADO]]-tbOrçamento[[#This Row],[VALOR MEDIDO]] -> 0 | J46: Contratado
A47: PQSUL | B47: =_xlfn.XLOOKUP(tbOrçamento[[#This Row],[OBRA]],tbObras[CÓDIGO],tbObras[NOME],"Não encontrado",0) -> Parque Sul | C47: PLANIALTIMÉTRICO | D47: PLANIALTIMÉTRICO | E47: 5000 | F47: =SUMIFS(tbContratos[VALOR CONTRATO],tbContratos[OBRA],tbOrçamento[[#This Row],[OBRA]],tbContratos[SUBDISCIPLINA],tbOrçamento[[#This Row],[SUBDISCIPLINA]]) -> 1300 | G47: =tbOrçamento[[#This Row],[ORÇAMENTO BASE ]]-tbOrçamento[[#This Row],[VALOR CONTRATADO]] -> 3700 | H47: =SUMIFS(tbContratos[VALOR MEDIDO],tbContratos[OBRA],tbOrçamento[[#This Row],[OBRA]],tbContratos[SUBDISCIPLINA],tbOrçamento[[#This Row],[SUBDISCIPLINA]]) -> 1300 | I47: =tbOrçamento[[#This Row],[VALOR CONTRATADO]]-tbOrçamento[[#This Row],[VALOR MEDIDO]] -> 0 | J47: Contratado
A48: PQSUL | B48: =_xlfn.XLOOKUP(tbOrçamento[[#This Row],[OBRA]],tbObras[CÓDIGO],tbObras[NOME],"Não encontrado",0) -> Parque Sul | C48: ARQUITETURA | D48: ARQUITERURA LEGAL | E48: 160000 | F48: =SUMIFS(tbContratos[VALOR CONTRATO],tbContratos[OBRA],tbOrçamento[[#This Row],[OBRA]],tbContratos[SUBDISCIPLINA],tbOrçamento[[#This Row],[SUBDISCIPLINA]]) -> 160000 | G48: =tbOrçamento[[#This Row],[ORÇAMENTO BASE ]]-tbOrçamento[[#This Row],[VALOR CONTRATADO]] -> 0 | H48: =SUMIFS(tbContratos[VALOR MEDIDO],tbContratos[OBRA],tbOrçamento[[#This Row],[OBRA]],tbContratos[SUBDISCIPLINA],tbOrçamento[[#This Row],[SUBDISCIPLINA]]) -> 64000 | I48: =tbOrçamento[[#This Row],[VALOR CONTRATADO]]-tbOrçamento[[#This Row],[VALOR MEDIDO]] -> 96000 | J48: Contratado
A49: PQSUL | B49: =_xlfn.XLOOKUP(tbOrçamento[[#This Row],[OBRA]],tbObras[CÓDIGO],tbObras[NOME],"Não encontrado",0) -> Parque Sul | C49: ARQUITETURA | D49: ARQUITETURA EXECUTIVA | E49: 59800 | F49: =SUMIFS(tbContratos[VALOR CONTRATO],tbContratos[OBRA],tbOrçamento[[#This Row],[OBRA]],tbContratos[SUBDISCIPLINA],tbOrçamento[[#This Row],[SUBDISCIPLINA]]) -> 0 | G49: =tbOrçamento[[#This Row],[ORÇAMENTO BASE ]]-tbOrçamento[[#This Row],[VALOR CONTRATADO]] -> 59800 | H49: =SUMIFS(tbContratos[VALOR MEDIDO],tbContratos[OBRA],tbOrçamento[[#This Row],[OBRA]],tbContratos[SUBDISCIPLINA],tbOrçamento[[#This Row],[SUBDISCIPLINA]]) -> 0 | I49: =tbOrçamento[[#This Row],[VALOR CONTRATADO]]-tbOrçamento[[#This Row],[VALOR MEDIDO]] -> 0 | J49: Em cotação
A50: PQSUL | B50: =_xlfn.XLOOKUP(tbOrçamento[[#This Row],[OBRA]],tbObras[CÓDIGO],tbObras[NOME],"Não encontrado",0) -> Parque Sul | C50: ESTRUTURA | D50: ESTRUTURA DE CONCRETO | E50: 225000 | F50: =SUMIFS(tbContratos[VALOR CONTRATO],tbContratos[OBRA],tbOrçamento[[#This Row],[OBRA]],tbContratos[SUBDISCIPLINA],tbOrçamento[[#This Row],[SUBDISCIPLINA]]) -> 210000 | G50: =tbOrçamento[[#This Row],[ORÇAMENTO BASE ]]-tbOrçamento[[#This Row],[VALOR CONTRATADO]] -> 15000 | H50: =SUMIFS(tbContratos[VALOR MEDIDO],tbContratos[OBRA],tbOrçamento[[#This Row],[OBRA]],tbContratos[SUBDISCIPLINA],tbOrçamento[[#This Row],[SUBDISCIPLINA]]) -> 31500 | I50: =tbOrçamento[[#This Row],[VALOR CONTRATADO]]-tbOrçamento[[#This Row],[VALOR MEDIDO]] -> 178500 | J50: Contratado
A51: PQSUL | B51: =_xlfn.XLOOKUP(tbOrçamento[[#This Row],[OBRA]],tbObras[CÓDIGO],tbObras[NOME],"Não encontrado",0) -> Parque Sul | C51: FUNDAÇÃO | D51: FUNDAÇÃO PROFUNDA | E51: 30000 | F51: =SUMIFS(tbContratos[VALOR CONTRATO],tbContratos[OBRA],tbOrçamento[[#This Row],[OBRA]],tbContratos[SUBDISCIPLINA],tbOrçamento[[#This Row],[SUBDISCIPLINA]]) -> 30000 | G51: =tbOrçamento[[#This Row],[ORÇAMENTO BASE ]]-tbOrçamento[[#This Row],[VALOR CONTRATADO]] -> 0 | H51: =SUMIFS(tbContratos[VALOR MEDIDO],tbContratos[OBRA],tbOrçamento[[#This Row],[OBRA]],tbContratos[SUBDISCIPLINA],tbOrçamento[[#This Row],[SUBDISCIPLINA]]) -> 0 | I51: =tbOrçamento[[#This Row],[VALOR CONTRATADO]]-tbOrçamento[[#This Row],[VALOR MEDIDO]] -> 30000 | J51: Contratado
A52: PQSUL | B52: =_xlfn.XLOOKUP(tbOrçamento[[#This Row],[OBRA]],tbObras[CÓDIGO],tbObras[NOME],"Não encontrado",0) -> Parque Sul | C52: FUNDAÇÃO | D52: PISO SUBSOLO | E52: 5000 | F52: =SUMIFS(tbContratos[VALOR CONTRATO],tbContratos[OBRA],tbOrçamento[[#This Row],[OBRA]],tbContratos[SUBDISCIPLINA],tbOrçamento[[#This Row],[SUBDISCIPLINA]]) -> 0 | G52: =tbOrçamento[[#This Row],[ORÇAMENTO BASE ]]-tbOrçamento[[#This Row],[VALOR CONTRATADO]] -> 5000 | H52: =SUMIFS(tbContratos[VALOR MEDIDO],tbContratos[OBRA],tbOrçamento[[#This Row],[OBRA]],tbContratos[SUBDISCIPLINA],tbOrçamento[[#This Row],[SUBDISCIPLINA]]) -> 0 | I52: =tbOrçamento[[#This Row],[VALOR CONTRATADO]]-tbOrçamento[[#This Row],[VALOR MEDIDO]] -> 0 | J52: A contratar
A53: PQSUL | B53: =_xlfn.XLOOKUP(tbOrçamento[[#This Row],[OBRA]],tbObras[CÓDIGO],tbObras[NOME],"Não encontrado",0) -> Parque Sul | C53: COMPLEMENTARES | D53: COMPLEMENTARES | E53: 188700 | F53: =SUMIFS(tbContratos[VALOR CONTRATO],tbContratos[OBRA],tbOrçamento[[#This Row],[OBRA]],tbContratos[SUBDISCIPLINA],tbOrçamento[[#This Row],[SUBDISCIPLINA]]) -> 179500 | G53: =tbOrçamento[[#This Row],[ORÇAMENTO BASE ]]-tbOrçamento[[#This Row],[VALOR CONTRATADO]] -> 9200 | H53: =SUMIFS(tbContratos[VALOR MEDIDO],tbContratos[OBRA],tbOrçamento[[#This Row],[OBRA]],tbContratos[SUBDISCIPLINA],tbOrçamento[[#This Row],[SUBDISCIPLINA]]) -> 53850 | I53: =tbOrçamento[[#This Row],[VALOR CONTRATADO]]-tbOrçamento[[#This Row],[VALOR MEDIDO]] -> 125650 | J53: Contratado
... A62: PQSUL | B62: =_xlfn.XLOOKUP(tbOrçamento[[#This Row],[OBRA]],tbObras[CÓDIGO],tbObras[NOME],"Não encontrado",0) -> Parque Sul | C62: INFRAESTRUTURA | D62: INTERLIGAÇÃO ELÉTRICA | E62: 10000 | F62: =SUMIFS(tbContratos[VALOR CONTRATO],tbContratos[OBRA],tbOrçamento[[#This Row],[OBRA]],tbContratos[SUBDISCIPLINA],tbOrçamento[[#This Row],[SUBDISCIPLINA]]) -> 0 | G62: =tbOrçamento[[#This Row],[ORÇAMENTO BASE ]]-tbOrçamento[[#This Row],[VALOR CONTRATADO]] -> 10000 | H62: =SUMIFS(tbContratos[VALOR MEDIDO],tbContratos[OBRA],tbOrçamento[[#This Row],[OBRA]],tbContratos[SUBDISCIPLINA],tbOrçamento[[#This Row],[SUBDISCIPLINA]]) -> 0 | I62: =tbOrçamento[[#This Row],[VALOR CONTRATADO]]-tbOrçamento[[#This Row],[VALOR MEDIDO]] -> 0 | J62: A contratar
A63: PQSUL | B63: =_xlfn.XLOOKUP(tbOrçamento[[#This Row],[OBRA]],tbObras[CÓDIGO],tbObras[NOME],"Não encontrado",0) -> Parque Sul | C63: INFRAESTRUTURA | D63: PROLONGAMENTO REDE | F63: =SUMIFS(tbContratos[VALOR CONTRATO],tbContratos[OBRA],tbOrçamento[[#This Row],[OBRA]],tbContratos[SUBDISCIPLINA],tbOrçamento[[#This Row],[SUBDISCIPLINA]]) -> 0 | G63: =tbOrçamento[[#This Row],[ORÇAMENTO BASE ]]-tbOrçamento[[#This Row],[VALOR CONTRATADO]] -> 0 | H63: =SUMIFS(tbContratos[VALOR MEDIDO],tbContratos[OBRA],tbOrçamento[[#This Row],[OBRA]],tbContratos[SUBDISCIPLINA],tbOrçamento[[#This Row],[SUBDISCIPLINA]]) -> 0 | I63: =tbOrçamento[[#This Row],[VALOR CONTRATADO]]-tbOrçamento[[#This Row],[VALOR MEDIDO]] -> 0 | J63: A contratar
A64: PQSUL | B64: =_xlfn.XLOOKUP(tbOrçamento[[#This Row],[OBRA]],tbObras[CÓDIGO],tbObras[NOME],"Não encontrado",0) -> Parque Sul | C64: ORÇAMENTO | D64: PARAMÉTRICO | E64: 10000 | F64: =SUMIFS(tbContratos[VALOR CONTRATO],tbContratos[OBRA],tbOrçamento[[#This Row],[OBRA]],tbContratos[SUBDISCIPLINA],tbOrçamento[[#This Row],[SUBDISCIPLINA]]) -> 12429.45 | G64: =tbOrçamento[[#This Row],[ORÇAMENTO BASE ]]-tbOrçamento[[#This Row],[VALOR CONTRATADO]] -> -2429.45 | H64: =SUMIFS(tbContratos[VALOR MEDIDO],tbContratos[OBRA],tbOrçamento[[#This Row],[OBRA]],tbContratos[SUBDISCIPLINA],tbOrçamento[[#This Row],[SUBDISCIPLINA]]) -> 3728.835 | I64: =tbOrçamento[[#This Row],[VALOR CONTRATADO]]-tbOrçamento[[#This Row],[VALOR MEDIDO]] -> 8700.615 | J64: Contratado
A65: PQSUL | B65: =_xlfn.XLOOKUP(tbOrçamento[[#This Row],[OBRA]],tbObras[CÓDIGO],tbObras[NOME],"Não encontrado",0) -> Parque Sul | C65: ORÇAMENTO | D65: EXECUTIVO | E65: 30000 | F65: =SUMIFS(tbContratos[VALOR CONTRATO],tbContratos[OBRA],tbOrçamento[[#This Row],[OBRA]],tbContratos[SUBDISCIPLINA],tbOrçamento[[#This Row],[SUBDISCIPLINA]]) -> 0 | G65: =tbOrçamento[[#This Row],[ORÇAMENTO BASE ]]-tbOrçamento[[#This Row],[VALOR CONTRATADO]] -> 30000 | H65: =SUMIFS(tbContratos[VALOR MEDIDO],tbContratos[OBRA],tbOrçamento[[#This Row],[OBRA]],tbContratos[SUBDISCIPLINA],tbOrçamento[[#This Row],[SUBDISCIPLINA]]) -> 0 | I65: =tbOrçamento[[#This Row],[VALOR CONTRATADO]]-tbOrçamento[[#This Row],[VALOR MEDIDO]] -> 0 | J65: A contratar
A66: PQSUL | B66: =_xlfn.XLOOKUP(tbOrçamento[[#This Row],[OBRA]],tbObras[CÓDIGO],tbObras[NOME],"Não encontrado",0) -> Parque Sul | C66: PLANEJAMENTO | D66: EXECUTIVO | E66: 20000 | F66: =SUMIFS(tbContratos[VALOR CONTRATO],tbContratos[OBRA],tbOrçamento[[#This Row],[OBRA]],tbContratos[SUBDISCIPLINA],tbOrçamento[[#This Row],[SUBDISCIPLINA]]) -> 0 | G66: =tbOrçamento[[#This Row],[ORÇAMENTO BASE ]]-tbOrçamento[[#This Row],[VALOR CONTRATADO]] -> 20000 | H66: =SUMIFS(tbContratos[VALOR MEDIDO],tbContratos[OBRA],tbOrçamento[[#This Row],[OBRA]],tbContratos[SUBDISCIPLINA],tbOrçamento[[#This Row],[SUBDISCIPLINA]]) -> 0 | I66: =tbOrçamento[[#This Row],[VALOR CONTRATADO]]-tbOrçamento[[#This Row],[VALOR MEDIDO]] -> 0 | J66: A contratar
A67: PQSUL | B67: =_xlfn.XLOOKUP(tbOrçamento[[#This Row],[OBRA]],tbObras[CÓDIGO],tbObras[NOME],"Não encontrado",0) -> Parque Sul | C67: LEGALIZAÇÃO | D67: LEGALIZAÇÃO | E67: 742740.9 | F67: =SUMIFS(tbContratos[VALOR CONTRATO],tbContratos[OBRA],tbOrçamento[[#This Row],[OBRA]],tbContratos[SUBDISCIPLINA],tbOrçamento[[#This Row],[SUBDISCIPLINA]]) -> 742740.9 | G67: =tbOrçamento[[#This Row],[ORÇAMENTO BASE ]]-tbOrçamento[[#This Row],[VALOR CONTRATADO]] -> 0 | H67: =SUMIFS(tbContratos[VALOR MEDIDO],tbContratos[OBRA],tbOrçamento[[#This Row],[OBRA]],tbContratos[SUBDISCIPLINA],tbOrçamento[[#This Row],[SUBDISCIPLINA]]) -> 7125 | I67: =tbOrçamento[[#This Row],[VALOR CONTRATADO]]-tbOrçamento[[#This Row],[VALOR MEDIDO]] -> 735615.9 | J67: A contratar
A68: UNA | B68: =_xlfn.XLOOKUP(tbOrçamento[[#This Row],[OBRA]],tbObras[CÓDIGO],tbObras[NOME],"Não encontrado",0) -> UNA | C68: SONDAGEM | D68: SONDAGEM | E68: 20000 | F68: =SUMIFS(tbContratos[VALOR CONTRATO],tbContratos[OBRA],tbOrçamento[[#This Row],[OBRA]],tbContratos[SUBDISCIPLINA],tbOrçamento[[#This Row],[SUBDISCIPLINA]]) -> 0 | G68: =tbOrçamento[[#This Row],[ORÇAMENTO BASE ]]-tbOrçamento[[#This Row],[VALOR CONTRATADO]] -> 20000 | H68: =SUMIFS(tbContratos[VALOR MEDIDO],tbContratos[OBRA],tbOrçamento[[#This Row],[OBRA]],tbContratos[SUBDISCIPLINA],tbOrçamento[[#This Row],[SUBDISCIPLINA]]) -> 0 | I68: =tbOrçamento[[#This Row],[VALOR CONTRATADO]]-tbOrçamento[[#This Row],[VALOR MEDIDO]] -> 0 | J68: Contratado
A69: UNA | B69: =_xlfn.XLOOKUP(tbOrçamento[[#This Row],[OBRA]],tbObras[CÓDIGO],tbObras[NOME],"Não encontrado",0) -> UNA | C69: PLANIALTIMÉTRICO | D69: PLANIALTIMÉTRICO | E69: 5000 | F69: =SUMIFS(tbContratos[VALOR CONTRATO],tbContratos[OBRA],tbOrçamento[[#This Row],[OBRA]],tbContratos[SUBDISCIPLINA],tbOrçamento[[#This Row],[SUBDISCIPLINA]]) -> 1100 | G69: =tbOrçamento[[#This Row],[ORÇAMENTO BASE ]]-tbOrçamento[[#This Row],[VALOR CONTRATADO]] -> 3900 | H69: =SUMIFS(tbContratos[VALOR MEDIDO],tbContratos[OBRA],tbOrçamento[[#This Row],[OBRA]],tbContratos[SUBDISCIPLINA],tbOrçamento[[#This Row],[SUBDISCIPLINA]]) -> 1100 | I69: =tbOrçamento[[#This Row],[VALOR CONTRATADO]]-tbOrçamento[[#This Row],[VALOR MEDIDO]] -> 0 | J69: Contratado
A70: UNA | B70: =_xlfn.XLOOKUP(tbOrçamento[[#This Row],[OBRA]],tbObras[CÓDIGO],tbObras[NOME],"Não encontrado",0) -> UNA | C70: ARQUITETURA | D70: ARQUITERURA LEGAL | E70: 40000 | F70: =SUMIFS(tbContratos[VALOR CONTRATO],tbContratos[OBRA],tbOrçamento[[#This Row],[OBRA]],tbContratos[SUBDISCIPLINA],tbOrçamento[[#This Row],[SUBDISCIPLINA]]) -> 40000 | G70: =tbOrçamento[[#This Row],[ORÇAMENTO BASE ]]-tbOrçamento[[#This Row],[VALOR CONTRATADO]] -> 0 | H70: =SUMIFS(tbContratos[VALOR MEDIDO],tbContratos[OBRA],tbOrçamento[[#This Row],[OBRA]],tbContratos[SUBDISCIPLINA],tbOrçamento[[#This Row],[SUBDISCIPLINA]]) -> 20000 | I70: =tbOrçamento[[#This Row],[VALOR CONTRATADO]]-tbOrçamento[[#This Row],[VALOR MEDIDO]] -> 20000 | J70: Contratado
A71: UNA | B71: =_xlfn.XLOOKUP(tbOrçamento[[#This Row],[OBRA]],tbObras[CÓDIGO],tbObras[NOME],"Não encontrado",0) -> UNA | C71: ESTRUTURA | D71: ESTRUTURA DE AÇO | E71: 15000 | F71: =SUMIFS(tbContratos[VALOR CONTRATO],tbContratos[OBRA],tbOrçamento[[#This Row],[OBRA]],tbContratos[SUBDISCIPLINA],tbOrçamento[[#This Row],[SUBDISCIPLINA]]) -> 13000 | G71: =tbOrçamento[[#This Row],[ORÇAMENTO BASE ]]-tbOrçamento[[#This Row],[VALOR CONTRATADO]] -> 2000 | H71: =SUMIFS(tbContratos[VALOR MEDIDO],tbContratos[OBRA],tbOrçamento[[#This Row],[OBRA]],tbContratos[SUBDISCIPLINA],tbOrçamento[[#This Row],[SUBDISCIPLINA]]) -> 6500 | I71: =tbOrçamento[[#This Row],[VALOR CONTRATADO]]-tbOrçamento[[#This Row],[VALOR MEDIDO]] -> 6500 | J71: Contratado
A72: UNA | B72: =_xlfn.XLOOKUP(tbOrçamento[[#This Row],[OBRA]],tbObras[CÓDIGO],tbObras[NOME],"Não encontrado",0) -> UNA | C72: FUNDAÇÃO | D72: FUNDAÇÃO PROFUNDA | E72: 10000 | F72: =SUMIFS(tbContratos[VALOR CONTRATO],tbContratos[OBRA],tbOrçamento[[#This Row],[OBRA]],tbContratos[SUBDISCIPLINA],tbOrçamento[[#This Row],[SUBDISCIPLINA]]) -> 10000 | G72: =tbOrçamento[[#This Row],[ORÇAMENTO BASE ]]-tbOrçamento[[#This Row],[VALOR CONTRATADO]] -> 0 | H72: =SUMIFS(tbContratos[VALOR MEDIDO],tbContratos[OBRA],tbOrçamento[[#This Row],[OBRA]],tbContratos[SUBDISCIPLINA],tbOrçamento[[#This Row],[SUBDISCIPLINA]]) -> 0 | I72: =tbOrçamento[[#This Row],[VALOR CONTRATADO]]-tbOrçamento[[#This Row],[VALOR MEDIDO]] -> 10000 | J72: Contratado
A73: UNA | B73: =_xlfn.XLOOKUP(tbOrçamento[[#This Row],[OBRA]],tbObras[CÓDIGO],tbObras[NOME],"Não encontrado",0) -> UNA | C73: FUNDAÇÃO | D73: FUNDAÇÃO SUPERFICIAL | E73: 1500 | F73: =SUMIFS(tbContratos[VALOR CONTRATO],tbContratos[OBRA],tbOrçamento[[#This Row],[OBRA]],tbContratos[SUBDISCIPLINA],tbOrçamento[[#This Row],[SUBDISCIPLINA]]) -> 16500 | G73: =tbOrçamento[[#This Row],[ORÇAMENTO BASE ]]-tbOrçamento[[#This Row],[VALOR CONTRATADO]] -> -15000 | H73: =SUMIFS(tbContratos[VALOR MEDIDO],tbContratos[OBRA],tbOrçamento[[#This Row],[OBRA]],tbContratos[SUBDISCIPLINA],tbOrçamento[[#This Row],[SUBDISCIPLINA]]) -> 0 | I73: =tbOrçamento[[#This Row],[VALOR CONTRATADO]]-tbOrçamento[[#This Row],[VALOR MEDIDO]] -> 16500 | J73: A contratar
A74: UNA | B74: =_xlfn.XLOOKUP(tbOrçamento[[#This Row],[OBRA]],tbObras[CÓDIGO],tbObras[NOME],"Não encontrado",0) -> UNA | C74: FUNDAÇÃO | D74: CONTENÇÕES | E74: 1500 | F74: =SUMIFS(tbContratos[VALOR CONTRATO],tbContratos[OBRA],tbOrçamento[[#This Row],[OBRA]],tbContratos[SUBDISCIPLINA],tbOrçamento[[#This Row],[SUBDISCIPLINA]]) -> 0 | G74: =tbOrçamento[[#This Row],[ORÇAMENTO BASE ]]-tbOrçamento[[#This Row],[VALOR CONTRATADO]] -> 1500 | H74: =SUMIFS(tbContratos[VALOR MEDIDO],tbContratos[OBRA],tbOrçamento[[#This Row],[OBRA]],tbContratos[SUBDISCIPLINA],tbOrçamento[[#This Row],[SUBDISCIPLINA]]) -> 0 | I74: =tbOrçamento[[#This Row],[VALOR CONTRATADO]]-tbOrçamento[[#This Row],[VALOR MEDIDO]] -> 0 | J74: A contratar
...

Sheet tbContratos
A1: CONTRATO_ID | B1: NUM SIENGE | C1: EMPRESA | D1: OBRA | E1: DISCIPLINA | F1: SUBDISCIPLINA | G1: VALOR CONTRATO | H1: VALOR MEDIDO | I1: SALDO A MEDIR | J1: PERCENTUAL MEDIDO
A2: CT001 | B2: 95 | C2: SOMA | D2: ALT | E2: =_xlfn.XLOOKUP(tbContratos[[#This Row],[EMPRESA]],tbFornecedores[FORNECEDOR],tbFornecedores[TIPO],"Não encontrado") -> ARQUITETURA | F2: ARQUITERURA LEGAL | G2: 108000 | H2: =SUMIFS(tbMedições[VALOR MEDIÇÃO],tbMedições[CONTRATO_ID],tbContratos[[#This Row],[CONTRATO_ID]],tbMedições[STATUS],"Pago")+SUMIFS(tbMedições[VALOR MEDIÇÃO],tbMedições[CONTRATO_ID],tbContratos[[#This Row],[CONTRATO_ID]],tbMedições[STATUS],"Medido") -> 102600 | I2: =tbContratos[[#This Row],[VALOR CONTRATO]]-tbContratos[[#This Row],[VALOR MEDIDO]] -> 5400 | J2: =tbContratos[[#This Row],[VALOR MEDIDO]]/tbContratos[[#This Row],[VALOR CONTRATO]] -> 0.95
A3: CT002 | B3: 593 | C3: SOMA | D3: GAL | E3: =_xlfn.XLOOKUP(tbContratos[[#This Row],[EMPRESA]],tbFornecedores[FORNECEDOR],tbFornecedores[TIPO],"Não encontrado") -> ARQUITETURA | F3: ARQUITERURA LEGAL | G3: 85680 | H3: =SUMIFS(tbMedições[VALOR MEDIÇÃO],tbMedições[CONTRATO_ID],tbContratos[[#This Row],[CONTRATO_ID]],tbMedições[STATUS],"Pago")+SUMIFS(tbMedições[VALOR MEDIÇÃO],tbMedições[CONTRATO_ID],tbContratos[[#This Row],[CONTRATO_ID]],tbMedições[STATUS],"Medido") -> 47124 | I3: =tbContratos[[#This Row],[VALOR CONTRATO]]-tbContratos[[#This Row],[VALOR MEDIDO]] -> 38556 | J3: =tbContratos[[#This Row],[VALOR MEDIDO]]/tbContratos[[#This Row],[VALOR CONTRATO]] -> 0.55
A4: CT003 | B4: 355 | C4: SOMA | D4: PQSUL | E4: =_xlfn.XLOOKUP(tbContratos[[#This Row],[EMPRESA]],tbFornecedores[FORNECEDOR],tbFornecedores[TIPO],"Não encontrado") -> ARQUITETURA | F4: ARQUITERURA LEGAL | G4: 160000 | H4: =SUMIFS(tbMedições[VALOR MEDIÇÃO],tbMedições[CONTRATO_ID],tbContratos[[#This Row],[CONTRATO_ID]],tbMedições[STATUS],"Pago")+SUMIFS(tbMedições[VALOR MEDIÇÃO],tbMedições[CONTRATO_ID],tbContratos[[#This Row],[CONTRATO_ID]],tbMedições[STATUS],"Medido") -> 64000 | I4: =tbContratos[[#This Row],[VALOR CONTRATO]]-tbContratos[[#This Row],[VALOR MEDIDO]] -> 96000 | J4: =tbContratos[[#This Row],[VALOR MEDIDO]]/tbContratos[[#This Row],[VALOR CONTRATO]] -> 0.4
A5: CT004 | B5: 42 | C5: SOMA | D5: LIB | E5: =_xlfn.XLOOKUP(tbContratos[[#This Row],[EMPRESA]],tbFornecedores[FORNECEDOR],tbFornecedores[TIPO],"Não encontrado") -> ARQUITETURA | F5: ARQUITERURA LEGAL | G5: 78000 | H5: =SUMIFS(tbMedições[VALOR MEDIÇÃO],tbMedições[CONTRATO_ID],tbContratos[[#This Row],[CONTRATO_ID]],tbMedições[STATUS],"Pago")+SUMIFS(tbMedições[VALOR MEDIÇÃO],tbMedições[CONTRATO_ID],tbContratos[[#This Row],[CONTRATO_ID]],tbMedições[STATUS],"Medido") -> 23400 | I5: =tbContratos[[#This Row],[VALOR CONTRATO]]-tbContratos[[#This Row],[VALOR MEDIDO]] -> 54600 | J5: =tbContratos[[#This Row],[VALOR MEDIDO]]/tbContratos[[#This Row],[VALOR CONTRATO]] -> 0.3
A6: CT005 | B6: 240 | C6: MBUIATE | D6: ALT | E6: =_xlfn.XLOOKUP(tbContratos[[#This Row],[EMPRESA]],tbFornecedores[FORNECEDOR],tbFornecedores[TIPO],"Não encontrado") -> ESTRUTURA | F6: ESTRUTURA DE CONCRETO | G6: 90000 | H6: =SUMIFS(tbMedições[VALOR MEDIÇÃO],tbMedições[CONTRATO_ID],tbContratos[[#This Row],[CONTRATO_ID]],tbMedições[STATUS],"Pago")+SUMIFS(tbMedições[VALOR MEDIÇÃO],tbMedições[CONTRATO_ID],tbContratos[[#This Row],[CONTRATO_ID]],tbMedições[STATUS],"Medido") -> 18000 | I6: =tbContratos[[#This Row],[VALOR CONTRATO]]-tbContratos[[#This Row],[VALOR MEDIDO]] -> 72000 | J6: =tbContratos[[#This Row],[VALOR MEDIDO]]/tbContratos[[#This Row],[VALOR CONTRATO]] -> 0.2
A7: CT006 | B7: 594 | C7: MBUIATE | D7: GAL | E7: =_xlfn.XLOOKUP(tbContratos[[#This Row],[EMPRESA]],tbFornecedores[FORNECEDOR],tbFornecedores[TIPO],"Não encontrado") -> ESTRUTURA | F7: ESTRUTURA DE CONCRETO | G7: 100000 | H7: =SUMIFS(tbMedições[VALOR MEDIÇÃO],tbMedições[CONTRATO_ID],tbContratos[[#This Row],[CONTRATO_ID]],tbMedições[STATUS],"Pago")+SUMIFS(tbMedições[VALOR MEDIÇÃO],tbMedições[CONTRATO_ID],tbContratos[[#This Row],[CONTRATO_ID]],tbMedições[STATUS],"Medido") -> 15000 | I7: =tbContratos[[#This Row],[VALOR CONTRATO]]-tbContratos[[#This Row],[VALOR MEDIDO]] -> 85000 | J7: =tbContratos[[#This Row],[VALOR MEDIDO]]/tbContratos[[#This Row],[VALOR CONTRATO]] -> 0.15
A8: CT007 | B8: 484 | C8: MBUIATE | D8: PQSUL | E8: =_xlfn.XLOOKUP(tbContratos[[#This Row],[EMPRESA]],tbFornecedores[FORNECEDOR],tbFornecedores[TIPO],"Não encontrado") -> ESTRUTURA | F8: ESTRUTURA DE CONCRETO | G8: 210000 | H8: =SUMIFS(tbMedições[VALOR MEDIÇÃO],tbMedições[CONTRATO_ID],tbContratos[[#This Row],[CONTRATO_ID]],tbMedições[STATUS],"Pago")+SUMIFS(tbMedições[VALOR MEDIÇÃO],tbMedições[CONTRATO_ID],tbContratos[[#This Row],[CONTRATO_ID]],tbMedições[STATUS],"Medido") -> 31500 | I8: =tbContratos[[#This Row],[VALOR CONTRATO]]-tbContratos[[#This Row],[VALOR MEDIDO]] -> 178500 | J8: =tbContratos[[#This Row],[VALOR MEDIDO]]/tbContratos[[#This Row],[VALOR CONTRATO]] -> 0.15
A9: CT008 | B9: 485 | C9: DALTON | D9: UNA | E9: =_xlfn.XLOOKUP(tbContratos[[#This Row],[EMPRESA]],tbFornecedores[FORNECEDOR],tbFornecedores[TIPO],"Não encontrado") -> INTERIORES | F9: INTERIORES | G9: 29000 | H9: =SUMIFS(tbMedições[VALOR MEDIÇÃO],tbMedições[CONTRATO_ID],tbContratos[[#This Row],[CONTRATO_ID]],tbMedições[STATUS],"Pago")+SUMIFS(tbMedições[VALOR MEDIÇÃO],tbMedições[CONTRATO_ID],tbContratos[[#This Row],[CONTRATO_ID]],tbMedições[STATUS],"Medido") -> 9404.1667 | I9: =tbContratos[[#This Row],[VALOR CONTRATO]]-tbContratos[[#This Row],[VALOR MEDIDO]] -> 19595.833 | J9: =tbContratos[[#This Row],[VALOR MEDIDO]]/tbContratos[[#This Row],[VALOR CONTRATO]] -> 0.32428161
A10: CT009 | B10: 595 | C10: DALTON | D10: GAL | E10: =_xlfn.XLOOKUP(tbContratos[[#This Row],[EMPRESA]],tbFornecedores[FORNECEDOR],tbFornecedores[TIPO],"Não encontrado") -> INTERIORES | F10: INTERIORES | G10: 70000 | H10: =SUMIFS(tbMedições[VALOR MEDIÇÃO],tbMedições[CONTRATO_ID],tbContratos[[#This Row],[CONTRATO_ID]],tbMedições[STATUS],"Pago")+SUMIFS(tbMedições[VALOR MEDIÇÃO],tbMedições[CONTRATO_ID],tbContratos[[#This Row],[CONTRATO_ID]],tbMedições[STATUS],"Medido") -> 14000 | I10: =tbContratos[[#This Row],[VALOR CONTRATO]]-tbContratos[[#This Row],[VALOR MEDIDO]] -> 56000 | J10: =tbContratos[[#This Row],[VALOR MEDIDO]]/tbContratos[[#This Row],[VALOR CONTRATO]] -> 0.2
A11: CT010 | B11: 310 | C11: KARINA | D11: ALT | E11: =_xlfn.XLOOKUP(tbContratos[[#This Row],[EMPRESA]],tbFornecedores[FORNECEDOR],tbFornecedores[TIPO],"Não encontrado") -> INTERIORES | F11: INTERIORES | G11: 39500 | H11: =SUMIFS(tbMedições[VALOR MEDIÇÃO],tbMedições[CONTRATO_ID],tbContratos[[#This Row],[CONTRATO_ID]],tbMedições[STATUS],"Pago")+SUMIFS(tbMedições[VALOR MEDIÇÃO],tbMedições[CONTRATO_ID],tbContratos[[#This Row],[CONTRATO_ID]],tbMedições[STATUS],"Medido") -> 20700 | I11: =tbContratos[[#This Row],[VALOR CONTRATO]]-tbContratos[[#This Row],[VALOR MEDIDO]] -> 18800 | J11: =tbContratos[[#This Row],[VALOR MEDIDO]]/tbContratos[[#This Row],[VALOR CONTRATO]] -> 0.52405063
A12: CT011 | B12: 451 | C12: GEOMETA | D12: ALT | E12: =_xlfn.XLOOKUP(tbContratos[[#This Row],[EMPRESA]],tbFornecedores[FORNECEDOR],tbFornecedores[TIPO],"Não encontrado") -> SONDAGEM | F12: SONDAGEM | G12: 17500.65 | H12: =SUMIFS(tbMedições[VALOR MEDIÇÃO],tbMedições[CONTRATO_ID],tbContratos[[#This Row],[CONTRATO_ID]],tbMedições[STATUS],"Pago")+SUMIFS(tbMedições[VALOR MEDIÇÃO],tbMedições[CONTRATO_ID],tbContratos[[#This Row],[CONTRATO_ID]],tbMedições[STATUS],"Medido") -> 17500.65 | I12: =tbContratos[[#This Row],[VALOR CONTRATO]]-tbContratos[[#This Row],[VALOR MEDIDO]] -> 0 | J12: =tbContratos[[#This Row],[VALOR MEDIDO]]/tbContratos[[#This Row],[VALOR CONTRATO]] -> 1
A13: CT012 | B13: 596 | C13: GEOMETA | D13: GAL | E13: =_xlfn.XLOOKUP(tbContratos[[#This Row],[EMPRESA]],tbFornecedores[FORNECEDOR],tbFornecedores[TIPO],"Não encontrado") -> SONDAGEM | F13: SONDAGEM | G13: 25313.28 | H13: =SUMIFS(tbMedições[VALOR MEDIÇÃO],tbMedições[CONTRATO_ID],tbContratos[[#This Row],[CONTRATO_ID]],tbMedições[STATUS],"Pago")+SUMIFS(tbMedições[VALOR MEDIÇÃO],tbMedições[CONTRATO_ID],tbContratos[[#This Row],[CONTRATO_ID]],tbMedições[STATUS],"Medido") -> 25313.28 | I13: =tbContratos[[#This Row],[VALOR CONTRATO]]-tbContratos[[#This Row],[VALOR MEDIDO]] -> 0 | J13: =tbContratos[[#This Row],[VALOR MEDIDO]]/tbContratos[[#This Row],[VALOR CONTRATO]] -> 1
... A18: CT017 | B18: 599 | C18: JP SERVIÇOS | D18: GAL | E18: =_xlfn.XLOOKUP(tbContratos[[#This Row],[EMPRESA]],tbFornecedores[FORNECEDOR],tbFornecedores[TIPO],"Não encontrado") -> SONDAGEM | F18: SONDAGEM | G18: 3640 | H18: =SUMIFS(tbMedições[VALOR MEDIÇÃO],tbMedições[CONTRATO_ID],tbContratos[[#This Row],[CONTRATO_ID]],tbMedições[STATUS],"Pago")+SUMIFS(tbMedições[VALOR MEDIÇÃO],tbMedições[CONTRATO_ID],tbContratos[[#This Row],[CONTRATO_ID]],tbMedições[STATUS],"Medido") -> 3640 | I18: =tbContratos[[#This Row],[VALOR CONTRATO]]-tbContratos[[#This Row],[VALOR MEDIDO]] -> 0 | J18: =tbContratos[[#This Row],[VALOR MEDIDO]]/tbContratos[[#This Row],[VALOR CONTRATO]] -> 1
A19: CT018 | C19: IDEAL | D19: ALT | E19: =_xlfn.XLOOKUP(tbContratos[[#This Row],[EMPRESA]],tbFornecedores[FORNECEDOR],tbFornecedores[TIPO],"Não encontrado") -> PLANIALTIMÉTRICO | F19: PLANIALTIMÉTRICO | G19: 4550 | H19: =SUMIFS(tbMedições[VALOR MEDIÇÃO],tbMedições[CONTRATO_ID],tbContratos[[#This Row],[CONTRATO_ID]],tbMedições[STATUS],"Pago")+SUMIFS(tbMedições[VALOR MEDIÇÃO],tbMedições[CONTRATO_ID],tbContratos[[#This Row],[CONTRATO_ID]],tbMedições[STATUS],"Medido") -> 4550 | I19: =tbContratos[[#This Row],[VALOR CONTRATO]]-tbContratos[[#This Row],[VALOR MEDIDO]] -> 0 | J19: =tbContratos[[#This Row],[VALOR MEDIDO]]/tbContratos[[#This Row],[VALOR CONTRATO]] -> 1
A20: CT019 | B20: 348 | C20: GEOMAP | D20: GAL | E20: =_xlfn.XLOOKUP(tbContratos[[#This Row],[EMPRESA]],tbFornecedores[FORNECEDOR],tbFornecedores[TIPO],"Não encontrado") -> PLANIALTIMÉTRICO | F20: PLANIALTIMÉTRICO | G20: 2850 | H20: =SUMIFS(tbMedições[VALOR MEDIÇÃO],tbMedições[CONTRATO_ID],tbContratos[[#This Row],[CONTRATO_ID]],tbMedições[STATUS],"Pago")+SUMIFS(tbMedições[VALOR MEDIÇÃO],tbMedições[CONTRATO_ID],tbContratos[[#This Row],[CONTRATO_ID]],tbMedições[STATUS],"Medido") -> 2850 | I20: =tbContratos[[#This Row],[VALOR CONTRATO]]-tbContratos[[#This Row],[VALOR MEDIDO]] -> 0 | J20: =tbContratos[[#This Row],[VALOR MEDIDO]]/tbContratos[[#This Row],[VALOR CONTRATO]] -> 1
A21: CT020 | B21: 348 | C21: GEOMAP | D21: PQSUL | E21: =_xlfn.XLOOKUP(tbContratos[[#This Row],[EMPRESA]],tbFornecedores[FORNECEDOR],tbFornecedores[TIPO],"Não encontrado") -> PLANIALTIMÉTRICO | F21: PLANIALTIMÉTRICO | G21: 1300 | H21: =SUMIFS(tbMedições[VALOR MEDIÇÃO],tbMedições[CONTRATO_ID],tbContratos[[#This Row],[CONTRATO_ID]],tbMedições[STATUS],"Pago")+SUMIFS(tbMedições[VALOR MEDIÇÃO],tbMedições[CONTRATO_ID],tbContratos[[#This Row],[CONTRATO_ID]],tbMedições[STATUS],"Medido") -> 1300 | I21: =tbContratos[[#This Row],[VALOR CONTRATO]]-tbContratos[[#This Row],[VALOR MEDIDO]] -> 0 | J21: =tbContratos[[#This Row],[VALOR MEDIDO]]/tbContratos[[#This Row],[VALOR CONTRATO]] -> 1
A22: CT021 | B22: 348 | C22: GEOMAP | D22: UNA | E22: =_xlfn.XLOOKUP(tbContratos[[#This Row],[EMPRESA]],tbFornecedores[FORNECEDOR],tbFornecedores[TIPO],"Não encontrado") -> PLANIALTIMÉTRICO | F22: PLANIALTIMÉTRICO | G22: 1100 | H22: =SUMIFS(tbMedições[VALOR MEDIÇÃO],tbMedições[CONTRATO_ID],tbContratos[[#This Row],[CONTRATO_ID]],tbMedições[STATUS],"Pago")+SUMIFS(tbMedições[VALOR MEDIÇÃO],tbMedições[CONTRATO_ID],tbContratos[[#This Row],[CONTRATO_ID]],tbMedições[STATUS],"Medido") -> 1100 | I22: =tbContratos[[#This Row],[VALOR CONTRATO]]-tbContratos[[#This Row],[VALOR MEDIDO]] -> 0 | J22: =tbContratos[[#This Row],[VALOR MEDIDO]]/tbContratos[[#This Row],[VALOR CONTRATO]] -> 1
A23: CT022 | B23: 348 | C23: GEOMAP | D23: STM | E23: =_xlfn.XLOOKUP(tbContratos[[#This Row],[EMPRESA]],tbFornecedores[FORNECEDOR],tbFornecedores[TIPO],"Não encontrado") -> PLANIALTIMÉTRICO | F23: PLANIALTIMÉTRICO | G23: 2635 | H23: =SUMIFS(tbMedições[VALOR MEDIÇÃO],tbMedições[CONTRATO_ID],tbContratos[[#This Row],[CONTRATO_ID]],tbMedições[STATUS],"Pago")+SUMIFS(tbMedições[VALOR MEDIÇÃO],tbMedições[CONTRATO_ID],tbContratos[[#This Row],[CONTRATO_ID]],tbMedições[STATUS],"Medido") -> 0 | I23: =tbContratos[[#This Row],[VALOR CONTRATO]]-tbContratos[[#This Row],[VALOR MEDIDO]] -> 2635 | J23: =tbContratos[[#This Row],[VALOR MEDIDO]]/tbContratos[[#This Row],[VALOR CONTRATO]] -> 0
A24: CT023 | B24: 348 | C24: GEOMAP | D24: SEFAZ | E24: =_xlfn.XLOOKUP(tbContratos[[#This Row],[EMPRESA]],tbFornecedores[FORNECEDOR],tbFornecedores[TIPO],"Não encontrado") -> PLANIALTIMÉTRICO | F24: PLANIALTIMÉTRICO | G24: 1800 | H24: =SUMIFS(tbMedições[VALOR MEDIÇÃO],tbMedições[CONTRATO_ID],tbContratos[[#This Row],[CONTRATO_ID]],tbMedições[STATUS],"Pago")+SUMIFS(tbMedições[VALOR MEDIÇÃO],tbMedições[CONTRATO_ID],tbContratos[[#This Row],[CONTRATO_ID]],tbMedições[STATUS],"Medido") -> 0 | I24: =tbContratos[[#This Row],[VALOR CONTRATO]]-tbContratos[[#This Row],[VALOR MEDIDO]] -> 1800 | J24: =tbContratos[[#This Row],[VALOR MEDIDO]]/tbContratos[[#This Row],[VALOR CONTRATO]] -> 0
A25: CT024 | B25: 344 | C25: GÊMEAS | D25: UNA | E25: =_xlfn.XLOOKUP(tbContratos[[#This Row],[EMPRESA]],tbFornecedores[FORNECEDOR],tbFornecedores[TIPO],"Não encontrado") -> ARQUITETURA | F25: ARQUITERURA LEGAL | G25: 40000 | H25: =SUMIFS(tbMedições[VALOR MEDIÇÃO],tbMedições[CONTRATO_ID],tbContratos[[#This Row],[CONTRATO_ID]],tbMedições[STATUS],"Pago")+SUMIFS(tbMedições[VALOR MEDIÇÃO],tbMedições[CONTRATO_ID],tbContratos[[#This Row],[CONTRATO_ID]],tbMedições[STATUS],"Medido") -> 20000 | I25: =tbContratos[[#This Row],[VALOR CONTRATO]]-tbContratos[[#This Row],[VALOR MEDIDO]] -> 20000 | J25: =tbContratos[[#This Row],[VALOR MEDIDO]]/tbContratos[[#This Row],[VALOR CONTRATO]] -> 0.5
A26: CT025 | B26: 296 | C26: EMMIG | D26: UNA | E26: =_xlfn.XLOOKUP(tbContratos[[#This Row],[EMPRESA]],tbFornecedores[FORNECEDOR],tbFornecedores[TIPO],"Não encontrado") -> ESTRUTURA | F26: ESTRUTURA DE AÇO | G26: 13000 | H26: =SUMIFS(tbMedições[VALOR MEDIÇÃO],tbMedições[CONTRATO_ID],tbContratos[[#This Row],[CONTRATO_ID]],tbMedições[STATUS],"Pago")+SUMIFS(tbMedições[VALOR MEDIÇÃO],tbMedições[CONTRATO_ID],tbContratos[[#This Row],[CONTRATO_ID]],tbMedições[STATUS],"Medido") -> 6500 | I26: =tbContratos[[#This Row],[VALOR CONTRATO]]-tbContratos[[#This Row],[VALOR MEDIDO]] -> 6500 | J26: =tbContratos[[#This Row],[VALOR MEDIDO]]/tbContratos[[#This Row],[VALOR CONTRATO]] -> 0.5
A27: CT026 | B27: 349 | C27: GEOMETRIA | D27: ALT | E27: =_xlfn.XLOOKUP(tbContratos[[#This Row],[EMPRESA]],tbFornecedores[FORNECEDOR],tbFornecedores[TIPO],"Não encontrado") -> FUNDAÇÃO | F27: FUNDAÇÃO PROFUNDA | G27: 25000 | H27: =SUMIFS(tbMedições[VALOR MEDIÇÃO],tbMedições[CONTRATO_ID],tbContratos[[#This Row],[CONTRATO_ID]],tbMedições[STATUS],"Pago")+SUMIFS(tbMedições[VALOR MEDIÇÃO],tbMedições[CONTRATO_ID],tbContratos[[#This Row],[CONTRATO_ID]],tbMedições[STATUS],"Medido") -> 0 | I27: =tbContratos[[#This Row],[VALOR CONTRATO]]-tbContratos[[#This Row],[VALOR MEDIDO]] -> 25000 | J27: =tbContratos[[#This Row],[VALOR MEDIDO]]/tbContratos[[#This Row],[VALOR CONTRATO]] -> 0
A28: CT027 | C28: GEOMETRIA | D28: GAL | E28: =_xlfn.XLOOKUP(tbContratos[[#This Row],[EMPRESA]],tbFornecedores[FORNECEDOR],tbFornecedores[TIPO],"Não encontrado") -> FUNDAÇÃO | F28: FUNDAÇÃO PROFUNDA | G28: 12000 | H28: =SUMIFS(tbMedições[VALOR MEDIÇÃO],tbMedições[CONTRATO_ID],tbContratos[[#This Row],[CONTRATO_ID]],tbMedições[STATUS],"Pago")+SUMIFS(tbMedições[VALOR MEDIÇÃO],tbMedições[CONTRATO_ID],tbContratos[[#This Row],[CONTRATO_ID]],tbMedições[STATUS],"Medido") -> 0 | I28: =tbContratos[[#This Row],[VALOR CONTRATO]]-tbContratos[[#This Row],[VALOR MEDIDO]] -> 12000 | J28: =tbContratos[[#This Row],[VALOR MEDIDO]]/tbContratos[[#This Row],[VALOR CONTRATO]] -> 0
A29: CT028 | B29: 349 | C29: GEOMETRIA | D29: PQSUL | E29: =_xlfn.XLOOKUP(tbContratos[[#This Row],[EMPRESA]],tbFornecedores[FORNECEDOR],tbFornecedores[TIPO],"Não encontrado") -> FUNDAÇÃO | F29: FUNDAÇÃO PROFUNDA | G29: 30000 | H29: =SUMIFS(tbMedições[VALOR MEDIÇÃO],tbMedições[CONTRATO_ID],tbContratos[[#This Row],[CONTRATO_ID]],tbMedições[STATUS],"Pago")+SUMIFS(tbMedições[VALOR MEDIÇÃO],tbMedições[CONTRATO_ID],tbContratos[[#This Row],[CONTRATO_ID]],tbMedições[STATUS],"Medido") -> 0 | I29: =tbContratos[[#This Row],[VALOR CONTRATO]]-tbContratos[[#This Row],[VALOR MEDIDO]] -> 30000 | J29: =tbContratos[[#This Row],[VALOR MEDIDO]]/tbContratos[[#This Row],[VALOR CONTRATO]] -> 0
A30: CT029 | B30: 349 | C30: GEOMETRIA | D30: UNA | E30: =_xlfn.XLOOKUP(tbContratos[[#This Row],[EMPRESA]],tbFornecedores[FORNECEDOR],tbFornecedores[TIPO],"Não encontrado") -> FUNDAÇÃO | F30: FUNDAÇÃO PROFUNDA | G30: 10000 | H30: =SUMIFS(tbMedições[VALOR MEDIÇÃO],tbMedições[CONTRATO_ID],tbContratos[[#This Row],[CONTRATO_ID]],tbMedições[STATUS],"Pago")+SUMIFS(tbMedições[VALOR MEDIÇÃO],tbMedições[CONTRATO_ID],tbContratos[[#This Row],[CONTRATO_ID]],tbMedições[STATUS],"Medido") -> 0 | I30: =tbContratos[[#This Row],[VALOR CONTRATO]]-tbContratos[[#This Row],[VALOR MEDIDO]] -> 10000 | J30: =tbContratos[[#This Row],[VALOR MEDIDO]]/tbContratos[[#This Row],[VALOR CONTRATO]] -> 0
A31: CT030 | B31: 265 | C31: VERTICAL | D31: ALT | E31: =_xlfn.XLOOKUP(tbContratos[[#This Row],[EMPRESA]],tbFornecedores[FORNECEDOR],tbFornecedores[TIPO],"Não encontrado") -> ORÇAMENTO | F31: PARAMÉTRICO | G31: 9000 | H31: =SUMIFS(tbMedições[VALOR MEDIÇÃO],tbMedições[CONTRATO_ID],tbContratos[[#This Row],[CONTRATO_ID]],tbMedições[STATUS],"Pago")+SUMIFS(tbMedições[VALOR MEDIÇÃO],tbMedições[CONTRATO_ID],tbContratos[[#This Row],[CONTRATO_ID]],tbMedições[STATUS],"Medido") -> 9000 | I31: =tbContratos[[#This Row],[VALOR CONTRATO]]-tbContratos[[#This Row],[VALOR MEDIDO]] -> 0 | J31: =tbContratos[[#This Row],[VALOR MEDIDO]]/tbContratos[[#This Row],[VALOR CONTRATO]] -> 1
A32: CT031 | C32: VERTICAL | D32: GAL | E32: =_xlfn.XLOOKUP(tbContratos[[#This Row],[EMPRESA]],tbFornecedores[FORNECEDOR],tbFornecedores[TIPO],"Não encontrado") -> ORÇAMENTO | F32: PARAMÉTRICO | G32: 6248.31 | H32: =SUMIFS(tbMedições[VALOR MEDIÇÃO],tbMedições[CONTRATO_ID],tbContratos[[#This Row],[CONTRATO_ID]],tbMedições[STATUS],"Pago")+SUMIFS(tbMedições[VALOR MEDIÇÃO],tbMedições[CONTRATO_ID],tbContratos[[#This Row],[CONTRATO_ID]],tbMedições[STATUS],"Medido") -> 1874.493 | I32: =tbContratos[[#This Row],[VALOR CONTRATO]]-tbContratos[[#This Row],[VALOR MEDIDO]] -> 4373.817 | J32: =tbContratos[[#This Row],[VALOR MEDIDO]]/tbContratos[[#This Row],[VALOR CONTRATO]] -> 0.3
A33: CT032 | B33: 434 | C33: VERTICAL | D33: PQSUL | E33: =_xlfn.XLOOKUP(tbContratos[[#This Row],[EMPRESA]],tbFornecedores[FORNECEDOR],tbFornecedores[TIPO],"Não encontrado") -> ORÇAMENTO | F33: PARAMÉTRICO | G33: 12429.45 | H33: =SUMIFS(tbMedições[VALOR MEDIÇÃO],tbMedições[CONTRATO_ID],tbContratos[[#This Row],[CONTRATO_ID]],tbMedições[STATUS],"Pago")+SUMIFS(tbMedições[VALOR MEDIÇÃO],tbMedições[CONTRATO_ID],tbContratos[[#This Row],[CONTRATO_ID]],tbMedições[STATUS],"Medido") -> 3728.835 | I33: =tbContratos[[#This Row],[VALOR CONTRATO]]-tbContratos[[#This Row],[VALOR MEDIDO]] -> 8700.615 | J33: =tbContratos[[#This Row],[VALOR MEDIDO]]/tbContratos[[#This Row],[VALOR CONTRATO]] -> 0.3
A34: CT033 | B34: 434 | C34: VERTICAL | D34: LIB | E34: =_xlfn.XLOOKUP(tbContratos[[#This Row],[EMPRESA]],tbFornecedores[FORNECEDOR],tbFornecedores[TIPO],"Não encontrado") -> ORÇAMENTO | F34: PARAMÉTRICO | G34: 8067.11 | H34: =SUMIFS(tbMedições[VALOR MEDIÇÃO],tbMedições[CONTRATO_ID],tbContratos[[#This Row],[CONTRATO_ID]],tbMedições[STATUS],"Pago")+SUMIFS(tbMedições[VALOR MEDIÇÃO],tbMedições[CONTRATO_ID],tbContratos[[#This Row],[CONTRATO_ID]],tbMedições[STATUS],"Medido") -> 2420.133 | I34: =tbContratos[[#This Row],[VALOR CONTRATO]]-tbContratos[[#This Row],[VALOR MEDIDO]] -> 5646.977 | J34: =tbContratos[[#This Row],[VALOR MEDIDO]]/tbContratos[[#This Row],[VALOR CONTRATO]] -> 0.3
A35: CT034 | B35: 434 | C35: VERTICAL | D35: UNA | E35: =_xlfn.XLOOKUP(tbContratos[[#This Row],[EMPRESA]],tbFornecedores[FORNECEDOR],tbFornecedores[TIPO],"Não encontrado") -> ORÇAMENTO | F35: PARAMÉTRICO | G35: 8255.14 | H35: =SUMIFS(tbMedições[VALOR MEDIÇÃO],tbMedições[CONTRATO_ID],tbContratos[[#This Row],[CONTRATO_ID]],tbMedições[STATUS],"Pago")+SUMIFS(tbMedições[VALOR MEDIÇÃO],tbMedições[CONTRATO_ID],tbContratos[[#This Row],[CONTRATO_ID]],tbMedições[STATUS],"Medido") -> 2476.542 | I35: =tbContratos[[#This Row],[VALOR CONTRATO]]-tbContratos[[#This Row],[VALOR MEDIDO]] -> 5778.598 | J35: =tbContratos[[#This Row],[VALOR MEDIDO]]/tbContratos[[#This Row],[VALOR CONTRATO]] -> 0.3
A36: CT035 | B36: 345 | C36: BINV | D36: ALT | E36: =_xlfn.XLOOKUP(tbContratos[[#This Row],[EMPRESA]],tbFornecedores[FORNECEDOR],tbFornecedores[TIPO],"Não encontrado") -> COMPLEMENTARES | F36: COMPLEMENTARES | G36: 150000 | H36: =SUMIFS(tbMedições[VALOR MEDIÇÃO],tbMedições[CONTRATO_ID],tbContratos[[#This Row],[CONTRATO_ID]],tbMedições[STATUS],"Pago")+SUMIFS(tbMedições[VALOR MEDIÇÃO],tbMedições[CONTRATO_ID],tbContratos[[#This Row],[CONTRATO_ID]],tbMedições[STATUS],"Medido") -> 67000 | I36: =tbContratos[[#This Row],[VALOR CONTRATO]]-tbContratos[[#This Row],[VALOR MEDIDO]] -> 83000 | J36: =tbContratos[[#This Row],[VALOR MEDIDO]]/tbContratos[[#This Row],[VALOR CONTRATO]] -> 0.44666667
A37: CT036 | B37: 346 | C37: BINV | D37: UNA | E37: =_xlfn.XLOOKUP(tbContratos[[#This Row],[EMPRESA]],tbFornecedores[FORNECEDOR],tbFornecedores[TIPO],"Não encontrado") -> COMPLEMENTARES | F37: COMPLEMENTARES | G37: 65450 | H37: =SUMIFS(tbMedições[VALOR MEDIÇÃO],tbMedições[CONTRATO_ID],tbContratos[[#This Row],[CONTRATO_ID]],tbMedições[STATUS],"Pago")+SUMIFS(tbMedições[VALOR MEDIÇÃO],tbMedições[CONTRATO_ID],tbContratos[[#This Row],[CONTRATO_ID]],tbMedições[STATUS],"Medido") -> 33180 | I37: =tbContratos[[#This Row],[VALOR CONTRATO]]-tbContratos[[#This Row],[VALOR MEDIDO]] -> 32270 | J37: =tbContratos[[#This Row],[VALOR MEDIDO]]/tbContratos[[#This Row],[VALOR CONTRATO]] -> 0.50695187
A38: CT037 | B38: 347 | C38: BINV | D38: MON | E38: =_xlfn.XLOOKUP(tbContratos[[#This Row],[EMPRESA]],tbFornecedores[FORNECEDOR],tbFornecedores[TIPO],"Não encontrado") -> COMPLEMENTARES | F38: COMPLEMENTARES | G38: 20000 | H38: =SUMIFS(tbMedições[VALOR MEDIÇÃO],tbMedições[CONTRATO_ID],tbContratos[[#This Row],[CONTRATO_ID]],tbMedições[STATUS],"Pago")+SUMIFS(tbMedições[VALOR MEDIÇÃO],tbMedições[CONTRATO_ID],tbContratos[[#This Row],[CONTRATO_ID]],tbMedições[STATUS],"Medido") -> 12000 | I38: =tbContratos[[#This Row],[VALOR CONTRATO]]-tbContratos[[#This Row],[VALOR MEDIDO]] -> 8000 | J38: =tbContratos[[#This Row],[VALOR MEDIDO]]/tbContratos[[#This Row],[VALOR CONTRATO]] -> 0.6
A39: CT038 | B39: 488 | C39: ARCIS | D39: PQSUL | E39: =_xlfn.XLOOKUP(tbContratos[[#This Row],[EMPRESA]],tbFornecedores[FORNECEDOR],tbFornecedores[TIPO],"Não encontrado") -> COMPLEMENTARES | F39: COMPLEMENTARES | G39: 179500 | H39: =SUMIFS(tbMedições[VALOR MEDIÇÃO],tbMedições[CONTRATO_ID],tbContratos[[#This Row],[CONTRATO_ID]],tbMedições[STATUS],"Pago")+SUMIFS(tbMedições[VALOR MEDIÇÃO],tbMedições[CONTRATO_ID],tbContratos[[#This Row],[CONTRATO_ID]],tbMedições[STATUS],"Medido") -> 53850 | I39: =tbContratos[[#This Row],[VALOR CONTRATO]]-tbContratos[[#This Row],[VALOR MEDIDO]] -> 125650 | J39: =tbContratos[[#This Row],[VALOR MEDIDO]]/tbContratos[[#This Row],[VALOR CONTRATO]] -> 0.3
